  <!--  <?xml version="1.0"?>  -->
    <robot name="sp1s">  
      <link name="base_link">  
        <visual>  
          <geometry>  
            <box size="0.27 .15 .003"/>  
          </geometry>  
          <material name="white">  
             <color rgba="1 1 1 .5"/>  
        </material>  
        </visual>  
      </link>  
        
      <link name="tyer_front_left">  
        <visual>  
          <geometry>  
           <cylinder length=".025" radius="0.034"></cylinder>  
          </geometry>  
          <material name="yellow">  
              <color rgba="1 1 0 1"/>  
          </material>    
        </visual>  
      </link>  
      
      <link name="tyer_front_right">  
        <visual>  
          <geometry>  
           <cylinder length=".025" radius="0.034"></cylinder>  
          </geometry>  
          <material name="yellow">    
              <color rgba="1 1 0 1"/>    
          </material>    
        </visual>  
      </link>  
        
      <link name="tyer_back_left">  
        <visual>  
          <geometry>  
           <cylinder length=".025" radius="0.034"></cylinder>  
          </geometry>  
          <material name="yellow">    
              <color rgba="1 1 0 1"/>    
          </material>    
        </visual>  
      </link>  
        
      <link name="tyer_back_right">  
        <visual>  
          <geometry>  
           <cylinder length=".025" radius="0.034"></cylinder>  
          </geometry>  
          <material name="yellow">    
              <color rgba="1 1 0 1"/>    
          </material>    
        </visual>  
      </link>  
        
      <joint name="base_to_front_left" type="continuous">  
        <origin rpy="1.57075  0  0" xyz="0.06  0.064  -0.011"/>  
        <parent link="base_link"/>  
        <child link="tyer_front_left"/>      
        <axis xyz="0 0 1"/>  
      </joint>  
      
      <joint name="base_to_front_right" type="continuous">  
        <origin rpy="1.57075  0  0" xyz="0.06  -0.064  -0.011"/>  
        <parent link="base_link"/>  
        <child link="tyer_front_right"/>      
        <axis xyz="0 0 1"/>  
      </joint>  
      
      <joint name="base_to_back_left" type="continuous">  
        <origin rpy="1.57075  0  0" xyz="-0.06  0.064  -0.011"/>  
        <parent link="base_link"/>  
        <child link="tyer_back_left"/>      
        <axis xyz="0 0 1"/>  
      </joint>  
      
      <joint name="base_to_back_right" type="continuous">  
        <origin rpy="1.57075  0  0" xyz="-0.06  -0.064  -0.011"/>  
        <parent link="base_link"/>  
        <child link="tyer_back_right"/>      
        <axis xyz="0 0 1"/>  
      </joint>  
     
      <link name="pillar_front_left">  
        <visual>  
          <geometry>  
           <cylinder length=".03" radius="0.0025"></cylinder>  
          </geometry>  
          <origin xyz="0 0 0.015"/>    
          <material name="silver">    
              <color rgba=".86 .86 .86 1"/>    
          </material>  
        </visual>  
      </link>  
      
      <link name="pillar_front_right">  
        <visual>  
          <geometry>  
           <cylinder length=".03" radius="0.0025"></cylinder>  
          </geometry>  
          <origin xyz="0 0 0.015"/>    
          <material name="silver">    
              <color rgba=".86 .86 .86 1"/>    
          </material>  
        </visual>  
      </link>  
      
      <link name="pillar_back_left">  
        <visual>  
          <geometry>  
           <cylinder length=".03" radius="0.0025"></cylinder>  
          </geometry>  
          <origin xyz="0 0 0.015"/>    
          <material name="silver">    
              <color rgba=".86 .86 .86 1"/>    
          </material>  
        </visual>  
      </link>  
      
      <link name="pillar_back_right">  
        <visual>  
          <geometry>  
           <cylinder length=".03" radius="0.0025"></cylinder>  
          </geometry>  
          <origin xyz="0 0 0.015"/>    
          <material name="silver">    
              <color rgba=".86 .86 .86 1"/>    
          </material>  
        </visual>  
      </link>  
      
      <joint name="base_to_pillar_front_left" type="fixed">  
        <origin xyz="0.13  0.07  0.0015"/>  
        <parent link="base_link"/>  
        <child link="pillar_front_left"/>  
      </joint>  
      
      <joint name="base_to_pillar_front_right" type="fixed">  
        <origin xyz="-0.13  0.07  0.0015"/>  
        <parent link="base_link"/>  
        <child link="pillar_front_right"/>  
      </joint>  
      
      <joint name="base_to_pillar_back_left" type="fixed">  
        <origin xyz="0.13  -0.07  0.0015"/>  
        <parent link="base_link"/>  
        <child link="pillar_back_left"/>  
      </joint>  
      
      <joint name="base_to_pillar_back_right" type="fixed">  
        <origin xyz="-0.13  -0.07  0.0015"/>  
        <parent link="base_link"/>  
        <child link="pillar_back_right"/>  
      </joint>  
      
      <link name="top_link">  
        <visual>  
          <geometry>  
            <box size="0.27 .15 .003"/>  
          </geometry>  
          <material name="white">  
             <color rgba="1 1 1 .5"/>  
        </material>  
        </visual>  
      </link>  
      
      <joint name="base_to_top" type="fixed">  
        <origin xyz="0  0  0.03"/>  
        <parent link="base_link"/>  
        <child link="top_link"/>  
      </joint>  



	
	<link
    name="rplidar_link">
    <inertial>
      <origin
        xyz="0 0 0"
        rpy="0 0 0" />
      <mass
        value="0.2839" />
		<inertia ixx="1e-6" ixy="0" ixz="0" iyy="1e-6" iyz="0" izz="1e-6" />
<!--      <inertia
        ixx="0.000163129354598355"
        ixy="-1.24540844318997E-19"
        ixz="1.65961724346785E-05"
        iyy="8.93708880724517E-19"
        iyz="-0.000249587191446841"
        izz="-8.64000875731417E-19" />
-->    
		</inertial>
    <visual>
      <origin
        xyz="0 0 0"
        rpy="0 0 0" />
      <geometry>
        <mesh
          filename="package://patrol_robot/meshes/rplidar2.STL" />
      </geometry>
      <material
        name="">
        <color
          rgba="0.79216 0.81961 0.93333 1" />
      </material>
    </visual>
    <collision>
      <origin
        xyz="0 0 0"
        rpy="0 0 0" />
      <geometry>
        <mesh
          filename="package://patrol_robot/meshes/rplidar2.STL" />
      </geometry>
    </collision>
  </link>
  <joint name="rplidar_joint" type="fixed">
<!--	<origin xyz="0 0 0.2164" rpy="0 3.14159265359 0"/>  -->
	<origin xyz="0 0 0.05" rpy="3.1415 0 0"/>
	<parent link="base_link"/>
	<child link="rplidar_link"/>
	</joint>

    </robot>  
